[2025-02-20T16:46:07.303+0100] {local_task_job_runner.py:123} INFO - ::group::Pre task execution logs
[2025-02-20T16:46:07.307+0100] {taskinstance.py:2614} INFO - Dependencies all met for dep_context=non-requeueable deps ti=<TaskInstance: etl_example.extract_data scheduled__2024-03-31T00:00:00+00:00 [queued]>
[2025-02-20T16:46:07.310+0100] {taskinstance.py:2614} INFO - Dependencies all met for dep_context=requeueable deps ti=<TaskInstance: etl_example.extract_data scheduled__2024-03-31T00:00:00+00:00 [queued]>
[2025-02-20T16:46:07.310+0100] {taskinstance.py:2867} INFO - Starting attempt 1 of 2
[2025-02-20T16:46:07.315+0100] {taskinstance.py:2890} INFO - Executing <Task(PythonOperator): extract_data> on 2024-03-31 00:00:00+00:00
[2025-02-20T16:46:07.318+0100] {standard_task_runner.py:72} INFO - Started process 36127 to run task
[2025-02-20T16:46:07.321+0100] {standard_task_runner.py:104} INFO - Running: ['airflow', 'tasks', 'run', 'etl_example', 'extract_data', 'scheduled__2024-03-31T00:00:00+00:00', '--job-id', '39', '--raw', '--subdir', 'DAGS_FOLDER/etl_dag.py', '--cfg-path', '/var/folders/d6/rl60yzz90jj_2v0s4gm257780000gn/T/tmpntuamivt']
[2025-02-20T16:46:07.323+0100] {standard_task_runner.py:105} INFO - Job 39: Subtask extract_data
[2025-02-20T16:46:07.567+0100] {task_command.py:467} INFO - Running <TaskInstance: etl_example.extract_data scheduled__2024-03-31T00:00:00+00:00 [running]> on host ajlas-macbook-air.local
[2025-02-20T16:46:07.681+0100] {taskinstance.py:3134} INFO - Exporting env vars: AIRFLOW_CTX_DAG_OWNER='ajlakorman' AIRFLOW_CTX_DAG_ID='etl_example' AIRFLOW_CTX_TASK_ID='extract_data' AIRFLOW_CTX_EXECUTION_DATE='2024-03-31T00:00:00+00:00' AIRFLOW_CTX_TRY_NUMBER='1' AIRFLOW_CTX_DAG_RUN_ID='scheduled__2024-03-31T00:00:00+00:00'
[2025-02-20T16:46:07.683+0100] {logging_mixin.py:190} INFO - Task instance is in running state
[2025-02-20T16:46:07.684+0100] {logging_mixin.py:190} INFO -  Previous state of the Task instance: queued
[2025-02-20T16:46:07.685+0100] {logging_mixin.py:190} INFO - Current task name:extract_data state:running start_date:2025-02-20 15:46:07.308074+00:00
[2025-02-20T16:46:07.685+0100] {logging_mixin.py:190} INFO - Dag name:etl_example and current dag run status:running
[2025-02-20T16:46:07.685+0100] {taskinstance.py:732} INFO - ::endgroup::
[2025-02-20T16:46:07.687+0100] {taskinstance.py:3313} ERROR - Task failed with exception
Traceback (most recent call last):
  File "/Users/ajlakorman/Desktop/Data-Mining-Projects/Apache_Airflow/venv/lib/python3.10/site-packages/airflow/models/taskinstance.py", line 768, in _execute_task
    result = _execute_callable(context=context, **execute_callable_kwargs)
  File "/Users/ajlakorman/Desktop/Data-Mining-Projects/Apache_Airflow/venv/lib/python3.10/site-packages/airflow/models/taskinstance.py", line 734, in _execute_callable
    return ExecutionCallableRunner(
  File "/Users/ajlakorman/Desktop/Data-Mining-Projects/Apache_Airflow/venv/lib/python3.10/site-packages/airflow/utils/operator_helpers.py", line 252, in run
    return self.func(*args, **kwargs)
  File "/Users/ajlakorman/Desktop/Data-Mining-Projects/Apache_Airflow/venv/lib/python3.10/site-packages/airflow/models/baseoperator.py", line 424, in wrapper
    return func(self, *args, **kwargs)
  File "/Users/ajlakorman/Desktop/Data-Mining-Projects/Apache_Airflow/venv/lib/python3.10/site-packages/airflow/operators/python.py", line 238, in execute
    return_value = self.execute_callable()
  File "/Users/ajlakorman/Desktop/Data-Mining-Projects/Apache_Airflow/venv/lib/python3.10/site-packages/airflow/operators/python.py", line 256, in execute_callable
    return runner.run(*self.op_args, **self.op_kwargs)
  File "/Users/ajlakorman/Desktop/Data-Mining-Projects/Apache_Airflow/venv/lib/python3.10/site-packages/airflow/utils/operator_helpers.py", line 252, in run
    return self.func(*args, **kwargs)
  File "/Users/ajlakorman/Desktop/Data-Mining-Projects/Apache_Airflow/airflow/dags/etl_dag.py", line 26, in extract_data
    df = pd.read_csv("/../../Billionaire Statistics Dataset Project/BillionairesStatisticsDataset.csv")
  File "/Users/ajlakorman/Desktop/Data-Mining-Projects/Apache_Airflow/venv/lib/python3.10/site-packages/pandas/io/parsers/readers.py", line 1026, in read_csv
    return _read(filepath_or_buffer, kwds)
  File "/Users/ajlakorman/Desktop/Data-Mining-Projects/Apache_Airflow/venv/lib/python3.10/site-packages/pandas/io/parsers/readers.py", line 620, in _read
    parser = TextFileReader(filepath_or_buffer, **kwds)
  File "/Users/ajlakorman/Desktop/Data-Mining-Projects/Apache_Airflow/venv/lib/python3.10/site-packages/pandas/io/parsers/readers.py", line 1620, in __init__
    self._engine = self._make_engine(f, self.engine)
  File "/Users/ajlakorman/Desktop/Data-Mining-Projects/Apache_Airflow/venv/lib/python3.10/site-packages/pandas/io/parsers/readers.py", line 1880, in _make_engine
    self.handles = get_handle(
  File "/Users/ajlakorman/Desktop/Data-Mining-Projects/Apache_Airflow/venv/lib/python3.10/site-packages/pandas/io/common.py", line 873, in get_handle
    handle = open(
FileNotFoundError: [Errno 2] No such file or directory: '/../../Billionaire Statistics Dataset Project/BillionairesStatisticsDataset.csv'
[2025-02-20T16:46:07.694+0100] {logging_mixin.py:190} INFO - Task instance in failure state
[2025-02-20T16:46:07.694+0100] {logging_mixin.py:190} INFO - Task start:2025-02-20 15:46:07.308074+00:00 end:2025-02-20 15:46:07.693906+00:00 duration:0.385832
[2025-02-20T16:46:07.694+0100] {logging_mixin.py:190} INFO - Task:<Task(PythonOperator): extract_data> dag:<DAG: etl_example> dagrun:<DagRun etl_example @ 2024-03-31 00:00:00+00:00: scheduled__2024-03-31T00:00:00+00:00, state:running, queued_at: 2025-02-20 15:46:06.031437+00:00. externally triggered: False>
[2025-02-20T16:46:07.695+0100] {logging_mixin.py:190} INFO - Failure caused by [Errno 2] No such file or directory: '/../../Billionaire Statistics Dataset Project/BillionairesStatisticsDataset.csv'
[2025-02-20T16:46:07.695+0100] {taskinstance.py:1226} INFO - Marking task as UP_FOR_RETRY. dag_id=etl_example, task_id=extract_data, run_id=scheduled__2024-03-31T00:00:00+00:00, execution_date=20240331T000000, start_date=20250220T154607, end_date=20250220T154607
[2025-02-20T16:46:07.706+0100] {taskinstance.py:341} INFO - ::group::Post task execution logs
[2025-02-20T16:46:07.707+0100] {standard_task_runner.py:124} ERROR - Failed to execute job 39 for task extract_data ([Errno 2] No such file or directory: '/../../Billionaire Statistics Dataset Project/BillionairesStatisticsDataset.csv'; 36127)
Traceback (most recent call last):
  File "/Users/ajlakorman/Desktop/Data-Mining-Projects/Apache_Airflow/venv/lib/python3.10/site-packages/airflow/task/task_runner/standard_task_runner.py", line 117, in _start_by_fork
    ret = args.func(args, dag=self.dag)
  File "/Users/ajlakorman/Desktop/Data-Mining-Projects/Apache_Airflow/venv/lib/python3.10/site-packages/airflow/cli/cli_config.py", line 49, in command
    return func(*args, **kwargs)
  File "/Users/ajlakorman/Desktop/Data-Mining-Projects/Apache_Airflow/venv/lib/python3.10/site-packages/airflow/utils/cli.py", line 116, in wrapper
    return f(*args, **kwargs)
  File "/Users/ajlakorman/Desktop/Data-Mining-Projects/Apache_Airflow/venv/lib/python3.10/site-packages/airflow/cli/commands/task_command.py", line 483, in task_run
    task_return_code = _run_task_by_selected_method(args, _dag, ti)
  File "/Users/ajlakorman/Desktop/Data-Mining-Projects/Apache_Airflow/venv/lib/python3.10/site-packages/airflow/cli/commands/task_command.py", line 256, in _run_task_by_selected_method
    return _run_raw_task(args, ti)
  File "/Users/ajlakorman/Desktop/Data-Mining-Projects/Apache_Airflow/venv/lib/python3.10/site-packages/airflow/cli/commands/task_command.py", line 341, in _run_raw_task
    return ti._run_raw_task(
  File "/Users/ajlakorman/Desktop/Data-Mining-Projects/Apache_Airflow/venv/lib/python3.10/site-packages/airflow/utils/session.py", line 97, in wrapper
    return func(*args, session=session, **kwargs)
  File "/Users/ajlakorman/Desktop/Data-Mining-Projects/Apache_Airflow/venv/lib/python3.10/site-packages/airflow/models/taskinstance.py", line 3006, in _run_raw_task
    return _run_raw_task(
  File "/Users/ajlakorman/Desktop/Data-Mining-Projects/Apache_Airflow/venv/lib/python3.10/site-packages/airflow/models/taskinstance.py", line 274, in _run_raw_task
    TaskInstance._execute_task_with_callbacks(
  File "/Users/ajlakorman/Desktop/Data-Mining-Projects/Apache_Airflow/venv/lib/python3.10/site-packages/airflow/models/taskinstance.py", line 3161, in _execute_task_with_callbacks
    result = self._execute_task(context, task_orig)
  File "/Users/ajlakorman/Desktop/Data-Mining-Projects/Apache_Airflow/venv/lib/python3.10/site-packages/airflow/models/taskinstance.py", line 3185, in _execute_task
    return _execute_task(self, context, task_orig)
  File "/Users/ajlakorman/Desktop/Data-Mining-Projects/Apache_Airflow/venv/lib/python3.10/site-packages/airflow/models/taskinstance.py", line 768, in _execute_task
    result = _execute_callable(context=context, **execute_callable_kwargs)
  File "/Users/ajlakorman/Desktop/Data-Mining-Projects/Apache_Airflow/venv/lib/python3.10/site-packages/airflow/models/taskinstance.py", line 734, in _execute_callable
    return ExecutionCallableRunner(
  File "/Users/ajlakorman/Desktop/Data-Mining-Projects/Apache_Airflow/venv/lib/python3.10/site-packages/airflow/utils/operator_helpers.py", line 252, in run
    return self.func(*args, **kwargs)
  File "/Users/ajlakorman/Desktop/Data-Mining-Projects/Apache_Airflow/venv/lib/python3.10/site-packages/airflow/models/baseoperator.py", line 424, in wrapper
    return func(self, *args, **kwargs)
  File "/Users/ajlakorman/Desktop/Data-Mining-Projects/Apache_Airflow/venv/lib/python3.10/site-packages/airflow/operators/python.py", line 238, in execute
    return_value = self.execute_callable()
  File "/Users/ajlakorman/Desktop/Data-Mining-Projects/Apache_Airflow/venv/lib/python3.10/site-packages/airflow/operators/python.py", line 256, in execute_callable
    return runner.run(*self.op_args, **self.op_kwargs)
  File "/Users/ajlakorman/Desktop/Data-Mining-Projects/Apache_Airflow/venv/lib/python3.10/site-packages/airflow/utils/operator_helpers.py", line 252, in run
    return self.func(*args, **kwargs)
  File "/Users/ajlakorman/Desktop/Data-Mining-Projects/Apache_Airflow/airflow/dags/etl_dag.py", line 26, in extract_data
    df = pd.read_csv("/../../Billionaire Statistics Dataset Project/BillionairesStatisticsDataset.csv")
  File "/Users/ajlakorman/Desktop/Data-Mining-Projects/Apache_Airflow/venv/lib/python3.10/site-packages/pandas/io/parsers/readers.py", line 1026, in read_csv
    return _read(filepath_or_buffer, kwds)
  File "/Users/ajlakorman/Desktop/Data-Mining-Projects/Apache_Airflow/venv/lib/python3.10/site-packages/pandas/io/parsers/readers.py", line 620, in _read
    parser = TextFileReader(filepath_or_buffer, **kwds)
  File "/Users/ajlakorman/Desktop/Data-Mining-Projects/Apache_Airflow/venv/lib/python3.10/site-packages/pandas/io/parsers/readers.py", line 1620, in __init__
    self._engine = self._make_engine(f, self.engine)
  File "/Users/ajlakorman/Desktop/Data-Mining-Projects/Apache_Airflow/venv/lib/python3.10/site-packages/pandas/io/parsers/readers.py", line 1880, in _make_engine
    self.handles = get_handle(
  File "/Users/ajlakorman/Desktop/Data-Mining-Projects/Apache_Airflow/venv/lib/python3.10/site-packages/pandas/io/common.py", line 873, in get_handle
    handle = open(
FileNotFoundError: [Errno 2] No such file or directory: '/../../Billionaire Statistics Dataset Project/BillionairesStatisticsDataset.csv'
[2025-02-20T16:46:07.723+0100] {local_task_job_runner.py:266} INFO - Task exited with return code 1
[2025-02-20T16:46:07.737+0100] {taskinstance.py:3901} INFO - 0 downstream tasks scheduled from follow-on schedule check
[2025-02-20T16:46:07.737+0100] {local_task_job_runner.py:245} INFO - ::endgroup::
